Workbook
Name diff: '[1]Regular Season Data'!$J:$J
Name gameid: '[1]Regular Season Data'!$A:$A
Name managers: '[1]Regular Season Data'!$D:$D
Name opponent: '[1]Regular Season Data'!$E:$E
Name outcome: '[1]Regular Season Data'!$K:$K
Name owners: [1]References!$A$2:$A$16
Name Owners: '[2]Main Page'!$B$6:$B$17
Name points: '[1]Regular Season Data'!$I:$I
Name Season: '[1]Regular Season Data'!$F:$F
Name teamnames: 'Summary Page'!$B$5:$B$14
Name teams: '[3]Summary Page'!$B$5:$B$16
Name teams: 'Summary Page (2)'!$B$5:$B$14
Name teams: 'Summary Page'!$B$5:$B$14
Name years: [1]References!$A$18:$A$30

Sheet Summary Page
B1: The League that Johnny Built - Historical Stats
B3: Historical Regular Season Table | M3: Highest Regular Season Weeks | T3: Best Regular Seasons All Time (Pts/G) | AE3: You vs Them | AM3: Them vs You | AZ3: You vs Them | BH3: Them vs You
B4: Team | C4: Wins | D4: Losses | E4: Pct | F4: Pts For | G4: Pts Agst | H4: Pts Per Game | I4: Avg Finish | J4: Avg Pts in W | K4: Avg Pts in L | M4: Rank | N4: Owner | O4: Opponent | P4: Season | Q4: Week | R4: Pts Scored | T4: Rank | U4: Owner | V4: Season | W4: Final Finish | X4: Wins | Y4: Losses | Z4: Pts | AB4: Matchup ID | AC4: Select Owner | AD4: Opponent | AE4: Pts/Wins | AF4: W Margin | AG4: Wins | AH4: Pts/Loss | AI4: L Margin | AJ4: Losses | AK4: Overall | AL4: Overall Margin | AM4: Pts/Wins | AN4: W Margin | AO4: Wins | AP4: Pts/Loss | AQ4: L Margin | AR4: Losses | AS4: Overall | AT4: Overall Margin | AU4: Total | AW4: Matchup ID | AX4: Select Owner | AY4: Opponent | AZ4: Pts/ Wins | BA4: W Margin | BB4: Wins | BC4: Pts/ Loss | BD4: L Margin | BE4: Losses | BF4: Overall | BG4: Overall Margin | BH4: Pts/ Wins | BI4: W Margin | BJ4: Wins | BK4: Pts/ Loss | BL4: L Margin | BM4: Losses | BN4: Overall | BO4: Overall Margin | BP4: Total
B5: Brian/Travis | C5: =COUNTIF('Regular Season'!R:R,'Summary Page'!B5) -> 86 | D5: =COUNTIF('Regular Season'!S:S,'Summary Page'!B5) -> 88 | E5: =IFERROR(C5/SUM(C5:D5),"") -> 0.49425287 | F5: =SUMIF('Regular Season'!R:R,'Summary Page'!B5,'Regular Season'!T:T)+SUMIF('Regular Season'!S:S,'Summary Page'!B5,'Regular Season'!U:U) -> 18422.78 | G5: =SUMIF('Regular Season'!R:R,'Summary Page'!B5,'Regular Season'!U:U)+SUMIF('Regular Season'!S:S,'Summary Page'!B5,'Regular Season'!T:T) -> 18199.36 | H5: =F5/SUM(C5:D5) -> 105.87805 | I5: =AVERAGEIF(Tables!C:C,'Summary Page'!B5,Tables!D:D) -> 6.1538462 | J5: =AVERAGEIF('Regular Season'!R:R,'Summary Page'!B5,'Regular Season'!T:T) -> 117.93698 | K5: =AVERAGEIF('Regular Season'!S:S,'Summary Page'!B5,'Regular Season'!U:U) -> 94.093182 | M5: 1 | N5: =VLOOKUP(M5,'Regular Season'!F:U,13,FALSE) -> Dave/Nolan | O5: =VLOOKUP(M5,'Regular Season'!F:U,14,FALSE) -> Walker/Cory | P5: =VLOOKUP(M5,'Regular Season'!F:U,3,FALSE) -> 2023 | Q5: =VLOOKUP(M5,'Regular Season'!F:U,4,FALSE) -> 13 | R5: =VLOOKUP(M5,'Regular Season'!F:U,15,FALSE) -> 190.28 | T5: 1 | U5: =VLOOKUP(T5,Tables!A:K,3,FALSE) -> Graham/Michael | V5: =VLOOKUP(T5,Tables!A:K,2,FALSE) -> 2025 | W5: =VLOOKUP(T5,Tables!A:K,5,FALSE) -> 3 | X5: =VLOOKUP(T5,Tables!A:K,6,FALSE) -> 13 | Y5: =VLOOKUP(T5,Tables!A:K,7,FALSE) -> 1 | Z5: =VLOOKUP(T5,Tables!A:K,11,FALSE) -> 138.41857 | AB5: 1 | AC5: Brian/Travis | AD5: Clay/Ryan | AE5: =AVERAGEIFS('Regular Season'!T:T,'Regular Season'!R:R,'Summary Page'!AC5,'Regular Season'!S:S,'Summary Page'!AD5) -> 104.04545 | AF5: =AE5-VLOOKUP(AC5,'Summary Page (2)'!$B$5:$K$14,9,FALSE) -> -13.891522 | AG5: =COUNTIFS('Regular Season'!R:R,'Summary Page'!AC5,'Regular Season'!S:S,'Summary Page'!AD5) -> 11 | AH5: =AVERAGEIFS('Regular Season'!U:U,'Regular Season'!S:S,'Summary Page'!AC5,'Regular Season'!R:R,'Summary Page'!AD5) -> 91.068889 | AI5: =AH5-VLOOKUP(AC5,'Summary Page (2)'!$B$5:$K$14,10,FALSE) -> -3.0242929 | AJ5: =COUNTIFS('Regular Season'!R:R,'Summary Page'!AD5,'Regular Season'!S:S,'Summary Page'!AC5) -> 9 | AK5: =IFERROR(((AG5*AE5)+(AH5*AJ5))/SUM(AG5,AJ5),"") -> 98.206 | AL5: =IFERROR(AK5-VLOOKUP(AC5,$B$5:$H$14,7,FALSE),"") -> -7.672046 | AM5: =AVERAGEIFS('Regular Season'!T:T,'Regular Season'!R:R,'Summary Page'!AD5,'Regular Season'!S:S,'Summary Page'!AC5) -> 122.76222 | AN5: =AM5-VLOOKUP(AD5,'Summary Page (2)'!$B$5:$K$14,9,FALSE) -> 3.2886738 | AO5: =COUNTIFS('Regular Season'!R:R,'Summary Page'!AD5,'Regular Season'!S:S,'Summary Page'!AC5) -> 9 | AP5: =AVERAGEIFS('Regular Season'!U:U,'Regular Season'!S:S,'Summary Page'!AD5,'Regular Season'!R:R,'Summary Page'!AC5) -> 82.661818 | AQ5: =AP5-VLOOKUP(AD5,'Summary Page (2)'!$B$5:$K$14,10,FALSE) -> -10.411515 | AR5: =COUNTIFS('Regular Season'!R:R,'Summary Page'!AC5,'Regular Season'!S:S,'Summary Page'!AD5) -> 11 | AS5: =IFERROR(((AO5*AM5)+(AP5*AR5))/SUM(AO5,AR5),"") -> 100.707 | AT5: =IFERROR(AS5-VLOOKUP(AD5,$B$5:$H$14,7,FALSE),"") -> -6.4767931 | AU5: =AL5-AT5 -> -1.1952529 | AW5: 88 | AX5: Walker/Cory | AY5: Graham/Michael | AZ5: 123.915 | BA5: 6.3284146 | BB5: 12 | BC5: 108.6 | BD5: 15.876471 | BE5: 5 | BF5: 119.41059 | BG5: 13.095255 | BH5: 128.028 | BI5: 5.6010556 | BJ5: 5 | BK5: 94.001667 | BL5: -4.3952564 | BM5: 12 | BN5: 104.00941 | BO5: -5.9219216 | BP5: 19.017176
B6: Clay/Ryan | C6: =COUNTIF('Regular Season'!R:R,'Summary Page'!B6) -> 93 | D6: =COUNTIF('Regular Season'!S:S,'Summary Page'!B6) -> 81 | E6: =IFERROR(C6/SUM(C6:D6),"") -> 0.53448276 | F6: =SUMIF('Regular Season'!R:R,'Summary Page'!B6,'Regular Season'!T:T)+SUMIF('Regular Season'!S:S,'Summary Page'!B6,'Regular Season'!U:U) -> 18649.98 | G6: =SUMIF('Regular Season'!R:R,'Summary Page'!B6,'Regular Season'!U:U)+SUMIF('Regular Season'!S:S,'Summary Page'!B6,'Regular Season'!T:T) -> 18283.58 | H6: =F6/SUM(C6:D6) -> 107.18379 | I6: =AVERAGEIF(Tables!C:C,'Summary Page'!B6,Tables!D:D) -> 4.6153846 | J6: =AVERAGEIF('Regular Season'!R:R,'Summary Page'!B6,'Regular Season'!T:T) -> 119.47355 | K6: =AVERAGEIF('Regular Season'!S:S,'Summary Page'!B6,'Regular Season'!U:U) -> 93.073333 | M6: 2 | N6: =VLOOKUP(M6,'Regular Season'!F:U,13,FALSE) -> Pat/Tucker | O6: =VLOOKUP(M6,'Regular Season'!F:U,14,FALSE) -> Dave/Nolan | P6: =VLOOKUP(M6,'Regular Season'!F:U,3,FALSE) -> 2022 | Q6: =VLOOKUP(M6,'Regular Season'!F:U,4,FALSE) -> 2 | R6: =VLOOKUP(M6,'Regular Season'!F:U,15,FALSE) -> 186.92 | T6: 2 | U6: =VLOOKUP(T6,Tables!A:K,3,FALSE) -> Eric/Blake | V6: =VLOOKUP(T6,Tables!A:K,2,FALSE) -> 2018 | W6: =VLOOKUP(T6,Tables!A:K,5,FALSE) -> 3 | X6: =VLOOKUP(T6,Tables!A:K,6,FALSE) -> 9 | Y6: =VLOOKUP(T6,Tables!A:K,7,FALSE) -> 4 | Z6: =VLOOKUP(T6,Tables!A:K,11,FALSE) -> 131.06923 | AB6: 2 | AC6: Brian/Travis | AD6: Dave/Nolan | AE6: =AVERAGEIFS('Regular Season'!T:T,'Regular Season'!R:R,'Summary Page'!AC6,'Regular Season'!S:S,'Summary Page'!AD6) -> 124.26333 | AF6: =AE6-VLOOKUP(AC6,'Summary Page (2)'!$B$5:$K$14,9,FALSE) -> 6.3263566 | AG6: =COUNTIFS('Regular Season'!R:R,'Summary Page'!AC6,'Regular Season'!S:S,'Summary Page'!AD6) -> 6 | AH6: =AVERAGEIFS('Regular Season'!U:U,'Regular Season'!S:S,'Summary Page'!AC6,'Regular Season'!R:R,'Summary Page'!AD6) -> 100.6925 | AI6: =AH6-VLOOKUP(AC6,'Summary Page (2)'!$B$5:$K$14,10,FALSE) -> 6.5993182 | AJ6: =COUNTIFS('Regular Season'!R:R,'Summary Page'!AD6,'Regular Season'!S:S,'Summary Page'!AC6) -> 8 | AK6: =IFERROR(((AG6*AE6)+(AH6*AJ6))/SUM(AG6,AJ6),"") -> 110.79429 | AL6: =IFERROR(AK6-VLOOKUP(AC6,$B$5:$H$14,7,FALSE),"") -> 4.9162397 | AM6: =AVERAGEIFS('Regular Season'!T:T,'Regular Season'!R:R,'Summary Page'!AD6,'Regular Season'!S:S,'Summary Page'!AC6) -> 117.6325 | AN6: =AM6-VLOOKUP(AD6,'Summary Page (2)'!$B$5:$K$14,9,FALSE) -> -4.0672531 | AO6: =COUNTIFS('Regular Season'!R:R,'Summary Page'!AD6,'Regular Season'!S:S,'Summary Page'!AC6) -> 8 | AP6: =AVERAGEIFS('Regular Season'!U:U,'Regular Season'!S:S,'Summary Page'!AD6,'Regular Season'!R:R,'Summary Page'!AC6) -> 96.153333 | AQ6: =AP6-VLOOKUP(AD6,'Summary Page (2)'!$B$5:$K$14,10,FALSE) -> 1.2772464 | AR6: =COUNTIFS('Regular Season'!R:R,'Summary Page'!AC6,'Regular Season'!S:S,'Summary Page'!AD6) -> 6 | AS6: =IFERROR(((AO6*AM6)+(AP6*AR6))/SUM(AO6,AR6),"") -> 108.42714 | AT6: =IFERROR(AS6-VLOOKUP(AD6,$B$5:$H$14,7,FALSE),"") -> 0.99199835 | AU6: =AL6-AT6 -> 3.9242414 | AW6: 51 | AX6: Eric/Blake | AY6: Graham/Michael | AZ6: 136.06727 | BA6: 13.672842 | BB6: 11 | BC6: 114.976 | BD6: 17.93262 | BE6: 5 | BF6: 129.47625 | BG6: 19.081317 | BH6: 136.164 | BI6: 13.737056 | BJ6: 5 | BK6: 100.67455 | BL6: 2.2776224 | BM6: 11 | BN6: 111.765 | BO6: 1.8336667 | BP6: 17.24765
B7: Dave/Nolan | C7: =COUNTIF('Regular Season'!R:R,'Summary Page'!B7) -> 81 | D7: =COUNTIF('Regular Season'!S:S,'Summary Page'!B7) -> 92 | E7: =IFERROR(C7/SUM(C7:D7),"") -> 0.46820809 | F7: =SUMIF('Regular Season'!R:R,'Summary Page'!B7,'Regular Season'!T:T)+SUMIF('Regular Season'!S:S,'Summary Page'!B7,'Regular Season'!U:U) -> 18586.28 | G7: =SUMIF('Regular Season'!R:R,'Summary Page'!B7,'Regular Season'!U:U)+SUMIF('Regular Season'!S:S,'Summary Page'!B7,'Regular Season'!T:T) -> 18598.64 | H7: =F7/SUM(C7:D7) -> 107.43514 | I7: =AVERAGEIF(Tables!C:C,'Summary Page'!B7,Tables!D:D) -> 6.0769231 | J7: =AVERAGEIF('Regular Season'!R:R,'Summary Page'!B7,'Regular Season'!T:T) -> 121.69975 | K7: =AVERAGEIF('Regular Season'!S:S,'Summary Page'!B7,'Regular Season'!U:U) -> 94.876087 | M7: 3 | N7: =VLOOKUP(M7,'Regular Season'!F:U,13,FALSE) -> Graham/Michael | O7: =VLOOKUP(M7,'Regular Season'!F:U,14,FALSE) -> Eric/Blake | P7: =VLOOKUP(M7,'Regular Season'!F:U,3,FALSE) -> 2023 | Q7: =VLOOKUP(M7,'Regular Season'!F:U,4,FALSE) -> 3 | R7: =VLOOKUP(M7,'Regular Season'!F:U,15,FALSE) -> 181.66 | T7: 3 | U7: =VLOOKUP(T7,Tables!A:K,3,FALSE) -> Dave/Nolan | V7: =VLOOKUP(T7,Tables!A:K,2,FALSE) -> 2019 | W7: =VLOOKUP(T7,Tables!A:K,5,FALSE) -> 4 | X7: =VLOOKUP(T7,Tables!A:K,6,FALSE) -> 10 | Y7: =VLOOKUP(T7,Tables!A:K,7,FALSE) -> 3 | Z7: =VLOOKUP(T7,Tables!A:K,11,FALSE) -> 127.13846 | AB7: 3 | AC7: Brian/Travis | AD7: David/Marshall | AE7: =AVERAGEIFS('Regular Season'!T:T,'Regular Season'!R:R,'Summary Page'!AC7,'Regular Season'!S:S,'Summary Page'!AD7) -> 112.822 | AF7: =AE7-VLOOKUP(AC7,'Summary Page (2)'!$B$5:$K$14,9,FALSE) -> -5.1149767 | AG7: =COUNTIFS('Regular Season'!R:R,'Summary Page'!AC7,'Regular Season'!S:S,'Summary Page'!AD7) -> 10 | AH7: =AVERAGEIFS('Regular Season'!U:U,'Regular Season'!S:S,'Summary Page'!AC7,'Regular Season'!R:R,'Summary Page'!AD7) -> 98.668889 | AI7: =AH7-VLOOKUP(AC7,'Summary Page (2)'!$B$5:$K$14,10,FALSE) -> 4.5757071 | AJ7: =COUNTIFS('Regular Season'!R:R,'Summary Page'!AD7,'Regular Season'!S:S,'Summary Page'!AC7) -> 9 | AK7: =IFERROR(((AG7*AE7)+(AH7*AJ7))/SUM(AG7,AJ7),"") -> 106.11789 | AL7: =IFERROR(AK7-VLOOKUP(AC7,$B$5:$H$14,7,FALSE),"") -> 0.23984876 | AM7: =AVERAGEIFS('Regular Season'!T:T,'Regular Season'!R:R,'Summary Page'!AD7,'Regular Season'!S:S,'Summary Page'!AC7) -> 116.73333 | AN7: =AM7-VLOOKUP(AD7,'Summary Page (2)'!$B$5:$K$14,9,FALSE) -> -2.4547826 | AO7: =COUNTIFS('Regular Season'!R:R,'Summary Page'!AD7,'Regular Season'!S:S,'Summary Page'!AC7) -> 9 | AP7: =AVERAGEIFS('Regular Season'!U:U,'Regular Season'!S:S,'Summary Page'!AD7,'Regular Season'!R:R,'Summary Page'!AC7) -> 92.364 | AQ7: =AP7-VLOOKUP(AD7,'Summary Page (2)'!$B$5:$K$14,10,FALSE) -> 1.8175849 | AR7: =COUNTIFS('Regular Season'!R:R,'Summary Page'!AC7,'Regular Season'!S:S,'Summary Page'!AD7) -> 10 | AS7: =IFERROR(((AO7*AM7)+(AP7*AR7))/SUM(AO7,AR7),"") -> 103.90737 | AT7: =IFERROR(AS7-VLOOKUP(AD7,$B$5:$H$14,7,FALSE),"") -> 2.0679398 | AU7: =AL7-AT7 -> -1.8280911 | AW7: 7 | AX7: Brian/Travis | AY7: Pat/Tucker | AZ7: 118.19231 | BA7: 1.0908791 | BB7: 13 | BC7: 93.115 | BD7: -0.45 | BE7: 8 | BF7: 108.63905 | BG7: 4.090381 | BH7: 105.1575 | BI7: -15.415743 | BJ7: 8 | BK7: 87.26 | BL7: -6.1378947 | BM7: 13 | BN7: 94.078095 | BO7: -12.726305 | BP7: 16.816686
B8: David/Marshall | C8: =COUNTIF('Regular Season'!R:R,'Summary Page'!B8) -> 69 | D8: =COUNTIF('Regular Season'!S:S,'Summary Page'!B8) -> 106 | E8: =IFERROR(C8/SUM(C8:D8),"") -> 0.39428571 | F8: =SUMIF('Regular Season'!R:R,'Summary Page'!B8,'Regular Season'!T:T)+SUMIF('Regular Season'!S:S,'Summary Page'!B8,'Regular Season'!U:U) -> 17821.9 | G8: =SUMIF('Regular Season'!R:R,'Summary Page'!B8,'Regular Season'!U:U)+SUMIF('Regular Season'!S:S,'Summary Page'!B8,'Regular Season'!T:T) -> 18752.74 | H8: =F8/SUM(C8:D8) -> 101.83943 | I8: =AVERAGEIF(Tables!C:C,'Summary Page'!B8,Tables!D:D) -> 7.1538462 | J8: =AVERAGEIF('Regular Season'!R:R,'Summary Page'!B8,'Regular Season'!T:T) -> 119.18812 | K8: =AVERAGEIF('Regular Season'!S:S,'Summary Page'!B8,'Regular Season'!U:U) -> 90.546415 | M8: 4 | N8: =VLOOKUP(M8,'Regular Season'!F:U,13,FALSE) -> Pat/Tucker | O8: =VLOOKUP(M8,'Regular Season'!F:U,14,FALSE) -> David/Marshall | P8: =VLOOKUP(M8,'Regular Season'!F:U,3,FALSE) -> 2022 | Q8: =VLOOKUP(M8,'Regular Season'!F:U,4,FALSE) -> 8 | R8: =VLOOKUP(M8,'Regular Season'!F:U,15,FALSE) -> 181.62 | T8: 4 | U8: =VLOOKUP(T8,Tables!A:K,3,FALSE) -> David/Marshall | V8: =VLOOKUP(T8,Tables!A:K,2,FALSE) -> 2021 | W8: =VLOOKUP(T8,Tables!A:K,5,FALSE) -> 5 | X8: =VLOOKUP(T8,Tables!A:K,6,FALSE) -> 9 | Y8: =VLOOKUP(T8,Tables!A:K,7,FALSE) -> 5 | Z8: =VLOOKUP(T8,Tables!A:K,11,FALSE) -> 125.53286 | AB8: 4 | AC8: Brian/Travis | AD8: Drew/Cam | AE8: =AVERAGEIFS('Regular Season'!T:T,'Regular Season'!R:R,'Summary Page'!AC8,'Regular Season'!S:S,'Summary Page'!AD8) -> 127.28222 | AF8: =AE8-VLOOKUP(AC8,'Summary Page (2)'!$B$5:$K$14,9,FALSE) -> 9.3452455 | AG8: =COUNTIFS('Regular Season'!R:R,'Summary Page'!AC8,'Regular Season'!S:S,'Summary Page'!AD8) -> 9 | AH8: =AVERAGEIFS('Regular Season'!U:U,'Regular Season'!S:S,'Summary Page'!AC8,'Regular Season'!R:R,'Summary Page'!AD8) -> 88.694286 | AI8: =AH8-VLOOKUP(AC8,'Summary Page (2)'!$B$5:$K$14,10,FALSE) -> -5.3988961 | AJ8: =COUNTIFS('Regular Season'!R:R,'Summary Page'!AD8,'Regular Season'!S:S,'Summary Page'!AC8) -> 14 | AK8: =IFERROR(((AG8*AE8)+(AH8*AJ8))/SUM(AG8,AJ8),"") -> 103.79391 | AL8: =IFERROR(AK8-VLOOKUP(AC8,$B$5:$H$14,7,FALSE),"") -> -2.0841329 | AM8: =AVERAGEIFS('Regular Season'!T:T,'Regular Season'!R:R,'Summary Page'!AD8,'Regular Season'!S:S,'Summary Page'!AC8) -> 114.69 | AN8: =AM8-VLOOKUP(AD8,'Summary Page (2)'!$B$5:$K$14,9,FALSE) -> -1.1502439 | AO8: =COUNTIFS('Regular Season'!R:R,'Summary Page'!AD8,'Regular Season'!S:S,'Summary Page'!AC8) -> 14 | AP8: =AVERAGEIFS('Regular Season'!U:U,'Regular Season'!S:S,'Summary Page'!AD8,'Regular Season'!R:R,'Summary Page'!AC8) -> 99.566667 | AQ8: =AP8-VLOOKUP(AD8,'Summary Page (2)'!$B$5:$K$14,10,FALSE) -> 6.7159058 | AR8: =COUNTIFS('Regular Season'!R:R,'Summary Page'!AC8,'Regular Season'!S:S,'Summary Page'!AD8) -> 9 | AS8: =IFERROR(((AO8*AM8)+(AP8*AR8))/SUM(AO8,AR8),"") -> 108.77217 | AT8: =IFERROR(AS8-VLOOKUP(AD8,$B$5:$H$14,7,FALSE),"") -> 5.0872889 | AU8: =AL8-AT8 -> -7.1714218 | AW8: 9 | AX8: Brian/Travis | AY8: Walker/Cory | AZ8: 122.24 | BA8: 5.1385714 | BB8: 8 | BC8: 67.91 | BD8: -25.655 | BE8: 4 | BF8: 104.13 | BG8: -0.41866667 | BH8: 108.1 | BI8: -9.4865854 | BJ8: 4 | BK8: 82.5 | BL8: -10.223529 | BM8: 8 | BN8: 91.033333 | BO8: -15.282 | BP8: 14.863333
B9: Drew/Cam | C9: =COUNTIF('Regular Season'!R:R,'Summary Page'!B9) -> 82 | D9: =COUNTIF('Regular Season'!S:S,'Summary Page'!B9) -> 92 | E9: =IFERROR(C9/SUM(C9:D9),"") -> 0.47126437 | F9: =SUMIF('Regular Season'!R:R,'Summary Page'!B9,'Regular Season'!T:T)+SUMIF('Regular Season'!S:S,'Summary Page'!B9,'Regular Season'!U:U) -> 18041.17 | G9: =SUMIF('Regular Season'!R:R,'Summary Page'!B9,'Regular Season'!U:U)+SUMIF('Regular Season'!S:S,'Summary Page'!B9,'Regular Season'!T:T) -> 18755.38 | H9: =F9/SUM(C9:D9) -> 103.68489 | I9: =AVERAGEIF(Tables!C:C,'Summary Page'!B9,Tables!D:D) -> 6.0769231 | J9: =AVERAGEIF('Regular Season'!R:R,'Summary Page'!B9,'Regular Season'!T:T) -> 115.84024 | K9: =AVERAGEIF('Regular Season'!S:S,'Summary Page'!B9,'Regular Season'!U:U) -> 92.850761 | M9: 5 | N9: =VLOOKUP(M9,'Regular Season'!F:U,13,FALSE) -> Eric/Blake | O9: =VLOOKUP(M9,'Regular Season'!F:U,14,FALSE) -> Graham/Michael | P9: =VLOOKUP(M9,'Regular Season'!F:U,3,FALSE) -> 2015 | Q9: =VLOOKUP(M9,'Regular Season'!F:U,4,FALSE) -> 5 | R9: =VLOOKUP(M9,'Regular Season'!F:U,15,FALSE) -> 177 | T9: 5 | U9: =VLOOKUP(T9,Tables!A:K,3,FALSE) -> Graham/Michael | V9: =VLOOKUP(T9,Tables!A:K,2,FALSE) -> 2019 | W9: =VLOOKUP(T9,Tables!A:K,5,FALSE) -> 3 | X9: =VLOOKUP(T9,Tables!A:K,6,FALSE) -> 8 | Y9: =VLOOKUP(T9,Tables!A:K,7,FALSE) -> 5 | Z9: =VLOOKUP(T9,Tables!A:K,11,FALSE) -> 122.97538 | AB9: 5 | AC9: Brian/Travis | AD9: Eric/Blake | AE9: =AVERAGEIFS('Regular Season'!T:T,'Regular Season'!R:R,'Summary Page'!AC9,'Regular Season'!S:S,'Summary Page'!AD9) -> 125.4525 | AF9: =AE9-VLOOKUP(AC9,'Summary Page (2)'!$B$5:$K$14,9,FALSE) -> 7.5155233 | AG9: =COUNTIFS('Regular Season'!R:R,'Summary Page'!AC9,'Regular Season'!S:S,'Summary Page'!AD9) -> 8 | AH9: =AVERAGEIFS('Regular Season'!U:U,'Regular Season'!S:S,'Summary Page'!AC9,'Regular Season'!R:R,'Summary Page'!AD9) -> 95.342857 | AI9: =AH9-VLOOKUP(AC9,'Summary Page (2)'!$B$5:$K$14,10,FALSE) -> 1.2496753 | AJ9: =COUNTIFS('Regular Season'!R:R,'Summary Page'!AD9,'Regular Season'!S:S,'Summary Page'!AC9) -> 7 | AK9: =IFERROR(((AG9*AE9)+(AH9*AJ9))/SUM(AG9,AJ9),"") -> 111.40133 | AL9: =IFERROR(AK9-VLOOKUP(AC9,$B$5:$H$14,7,FALSE),"") -> 5.5232874 | AM9: =AVERAGEIFS('Regular Season'!T:T,'Regular Season'!R:R,'Summary Page'!AD9,'Regular Season'!S:S,'Summary Page'!AC9) -> 116.03429 | AN9: =AM9-VLOOKUP(AD9,'Summary Page (2)'!$B$5:$K$14,9,FALSE) -> -6.3083516 | AO9: =COUNTIFS('Regular Season'!R:R,'Summary Page'!AD9,'Regular Season'!S:S,'Summary Page'!AC9) -> 7 | AP9: =AVERAGEIFS('Regular Season'!U:U,'Regular Season'!S:S,'Summary Page'!AD9,'Regular Season'!R:R,'Summary Page'!AC9) -> 106.4175 | AQ9: =AP9-VLOOKUP(AD9,'Summary Page (2)'!$B$5:$K$14,10,FALSE) -> 10.0175 | AR9: =COUNTIFS('Regular Season'!R:R,'Summary Page'!AC9,'Regular Season'!S:S,'Summary Page'!AD9) -> 8 | AS9: =IFERROR(((AO9*AM9)+(AP9*AR9))/SUM(AO9,AR9),"") -> 110.90533 | AT9: =IFERROR(AS9-VLOOKUP(AD9,$B$5:$H$14,7,FALSE),"") -> 0.93763218 | AU9: =AL9-AT9 -> 4.5856552 | AW9: 67 | AX9: Pat/Tucker | AY9: David/Marshall | AZ9: 127.55273 | BA9: 6.979484 | BB9: 11 | BC9: 73.033333 | BD9: -20.364561 | BE9: 3 | BF9: 115.87 | BG9: 9.0656 | BH9: 118.69333 | BI9: 0.83011905 | BJ9: 3 | BK9: 90.872727 | BL9: -0.023017408 | BM9: 11 | BN9: 96.834286 | BO9: -4.1293143 | BP9: 13.194914
B10: Eric/Blake | C10: =COUNTIF('Regular Season'!R:R,'Summary Page'!B10) -> 91 | D10: =COUNTIF('Regular Season'!S:S,'Summary Page'!B10) -> 83 | E10: =IFERROR(C10/SUM(C10:D10),"") -> 0.52298851 | F10: =SUMIF('Regular Season'!R:R,'Summary Page'!B10,'Regular Season'!T:T)+SUMIF('Regular Season'!S:S,'Summary Page'!B10,'Regular Season'!U:U) -> 19134.38 | G10: =SUMIF('Regular Season'!R:R,'Summary Page'!B10,'Regular Season'!U:U)+SUMIF('Regular Season'!S:S,'Summary Page'!B10,'Regular Season'!T:T) -> 18865.58 | H10: =F10/SUM(C10:D10) -> 109.9677 | I10: =AVERAGEIF(Tables!C:C,'Summary Page'!B10,Tables!D:D) -> 4.8461538 | J10: =AVERAGEIF('Regular Season'!R:R,'Summary Page'!B10,'Regular Season'!T:T) -> 122.34264 | K10: =AVERAGEIF('Regular Season'!S:S,'Summary Page'!B10,'Regular Season'!U:U) -> 96.4 | M10: 6 | N10: =VLOOKUP(M10,'Regular Season'!F:U,13,FALSE) -> Clay/Ryan | O10: =VLOOKUP(M10,'Regular Season'!F:U,14,FALSE) -> Dave/Nolan | P10: =VLOOKUP(M10,'Regular Season'!F:U,3,FALSE) -> 2019 | Q10: =VLOOKUP(M10,'Regular Season'!F:U,4,FALSE) -> 5 | R10: =VLOOKUP(M10,'Regular Season'!F:U,15,FALSE) -> 176.56 | T10: 6 | U10: =VLOOKUP(T10,Tables!A:K,3,FALSE) -> Clay/Ryan | V10: =VLOOKUP(T10,Tables!A:K,2,FALSE) -> 2019 | W10: =VLOOKUP(T10,Tables!A:K,5,FALSE) -> 6 | X10: =VLOOKUP(T10,Tables!A:K,6,FALSE) -> 6 | Y10: =VLOOKUP(T10,Tables!A:K,7,FALSE) -> 7 | Z10: =VLOOKUP(T10,Tables!A:K,11,FALSE) -> 122.44923 | AB10: 6 | AC10: Brian/Travis | AD10: Graham/Michael | AE10: =AVERAGEIFS('Regular Season'!T:T,'Regular Season'!R:R,'Summary Page'!AC10,'Regular Season'!S:S,'Summary Page'!AD10) -> 114.09556 | AF10: =AE10-VLOOKUP(AC10,'Summary Page (2)'!$B$5:$K$14,9,FALSE) -> -3.8414212 | AG10: =COUNTIFS('Regular Season'!R:R,'Summary Page'!AC10,'Regular Season'!S:S,'Summary Page'!AD10) -> 9 | AH10: =AVERAGEIFS('Regular Season'!U:U,'Regular Season'!S:S,'Summary Page'!AC10,'Regular Season'!R:R,'Summary Page'!AD10) -> 98.785455 | AI10: =AH10-VLOOKUP(AC10,'Summary Page (2)'!$B$5:$K$14,10,FALSE) -> 4.6922727 | AJ10: =COUNTIFS('Regular Season'!R:R,'Summary Page'!AD10,'Regular Season'!S:S,'Summary Page'!AC10) -> 11 | AK10: =IFERROR(((AG10*AE10)+(AH10*AJ10))/SUM(AG10,AJ10),"") -> 105.675 | AL10: =IFERROR(AK10-VLOOKUP(AC10,$B$5:$H$14,7,FALSE),"") -> -0.20304598 | AM10: =AVERAGEIFS('Regular Season'!T:T,'Regular Season'!R:R,'Summary Page'!AD10,'Regular Season'!S:S,'Summary Page'!AC10) -> 128.71273 | AN10: =AM10-VLOOKUP(AD10,'Summary Page (2)'!$B$5:$K$14,9,FALSE) -> 3.5540606 | AO10: =COUNTIFS('Regular Season'!R:R,'Summary Page'!AD10,'Regular Season'!S:S,'Summary Page'!AC10) -> 11 | AP10: =AVERAGEIFS('Regular Season'!U:U,'Regular Season'!S:S,'Summary Page'!AD10,'Regular Season'!R:R,'Summary Page'!AC10) -> 92.804444 | AQ10: =AP10-VLOOKUP(AD10,'Summary Page (2)'!$B$5:$K$14,10,FALSE) -> -6.1426984 | AR10: =COUNTIFS('Regular Season'!R:R,'Summary Page'!AC10,'Regular Season'!S:S,'Summary Page'!AD10) -> 9 | AS10: =IFERROR(((AO10*AM10)+(AP10*AR10))/SUM(AO10,AR10),"") -> 112.554 | AT10: =IFERROR(AS10-VLOOKUP(AD10,$B$5:$H$14,7,FALSE),"") -> 0.049172414 | AU10: =AL10-AT10 -> -0.25221839 | AW10: 79 | AX10: Trent/Colin | AY10: Graham/Michael | AZ10: 128.782 | BA10: 7.6957079 | BB10: 10 | BC10: 104.74286 | BD10: 9.9569555 | BE10: 7 | BF10: 118.88353 | BG10: 8.4927294 | BH10: 113.75429 | BI10: -8.6726587 | BJ10: 7 | BK10: 100.354 | BL10: 1.9570769 | BM10: 10 | BN10: 105.87176 | BO10: -4.0595686 | BP10: 12.552298
B11: Graham/Michael | C11: =COUNTIF('Regular Season'!R:R,'Summary Page'!B11) -> 90 | D11: =COUNTIF('Regular Season'!S:S,'Summary Page'!B11) -> 84 | E11: =IFERROR(C11/SUM(C11:D11),"") -> 0.51724138 | F11: =SUMIF('Regular Season'!R:R,'Summary Page'!B11,'Regular Season'!T:T)+SUMIF('Regular Season'!S:S,'Summary Page'!B11,'Regular Season'!U:U) -> 19575.84 | G11: =SUMIF('Regular Season'!R:R,'Summary Page'!B11,'Regular Season'!U:U)+SUMIF('Regular Season'!S:S,'Summary Page'!B11,'Regular Season'!T:T) -> 19246.16 | H11: =F11/SUM(C11:D11) -> 112.50483 | I11: =AVERAGEIF(Tables!C:C,'Summary Page'!B11,Tables!D:D) -> 5.0769231 | J11: =AVERAGEIF('Regular Season'!R:R,'Summary Page'!B11,'Regular Season'!T:T) -> 125.15867 | K11: =AVERAGEIF('Regular Season'!S:S,'Summary Page'!B11,'Regular Season'!U:U) -> 98.947143 | M11: 7 | N11: =VLOOKUP(M11,'Regular Season'!F:U,13,FALSE) -> Brian/Travis | O11: =VLOOKUP(M11,'Regular Season'!F:U,14,FALSE) -> Walker/Cory | P11: =VLOOKUP(M11,'Regular Season'!F:U,3,FALSE) -> 2020 | Q11: =VLOOKUP(M11,'Regular Season'!F:U,4,FALSE) -> 12 | R11: =VLOOKUP(M11,'Regular Season'!F:U,15,FALSE) -> 174.08 | T11: 7 | U11: =VLOOKUP(T11,Tables!A:K,3,FALSE) -> Graham/Michael | V11: =VLOOKUP(T11,Tables!A:K,2,FALSE) -> 2014 | W11: =VLOOKUP(T11,Tables!A:K,5,FALSE) -> 5 | X11: =VLOOKUP(T11,Tables!A:K,6,FALSE) -> 6 | Y11: =VLOOKUP(T11,Tables!A:K,7,FALSE) -> 7 | Z11: =VLOOKUP(T11,Tables!A:K,11,FALSE) -> 122.34615 | AB11: 7 | AC11: Brian/Travis | AD11: Pat/Tucker | AE11: =AVERAGEIFS('Regular Season'!T:T,'Regular Season'!R:R,'Summary Page'!AC11,'Regular Season'!S:S,'Summary Page'!AD11) -> 118.55867 | AF11: =AE11-VLOOKUP(AC11,'Summary Page (2)'!$B$5:$K$14,9,FALSE) -> 0.62168992 | AG11: =COUNTIFS('Regular Season'!R:R,'Summary Page'!AC11,'Regular Season'!S:S,'Summary Page'!AD11) -> 15 | AH11: =AVERAGEIFS('Regular Season'!U:U,'Regular Season'!S:S,'Summary Page'!AC11,'Regular Season'!R:R,'Summary Page'!AD11) -> 94.171111 | AI11: =AH11-VLOOKUP(AC11,'Summary Page (2)'!$B$5:$K$14,10,FALSE) -> 0.077929293 | AJ11: =COUNTIFS('Regular Season'!R:R,'Summary Page'!AD11,'Regular Season'!S:S,'Summary Page'!AC11) -> 9 | AK11: =IFERROR(((AG11*AE11)+(AH11*AJ11))/SUM(AG11,AJ11),"") -> 109.41333 | AL11: =IFERROR(AK11-VLOOKUP(AC11,$B$5:$H$14,7,FALSE),"") -> 3.5352874 | AM11: =AVERAGEIFS('Regular Season'!T:T,'Regular Season'!R:R,'Summary Page'!AD11,'Regular Season'!S:S,'Summary Page'!AC11) -> 106.42444 | AN11: =AM11-VLOOKUP(AD11,'Summary Page (2)'!$B$5:$K$14,9,FALSE) -> -14.017937 | AO11: =COUNTIFS('Regular Season'!R:R,'Summary Page'!AD11,'Regular Season'!S:S,'Summary Page'!AC11) -> 9 | AP11: =AVERAGEIFS('Regular Season'!U:U,'Regular Season'!S:S,'Summary Page'!AD11,'Regular Season'!R:R,'Summary Page'!AC11) -> 86.406667 | AQ11: =AP11-VLOOKUP(AD11,'Summary Page (2)'!$B$5:$K$14,10,FALSE) -> -8.0990152 | AR11: =COUNTIFS('Regular Season'!R:R,'Summary Page'!AC11,'Regular Season'!S:S,'Summary Page'!AD11) -> 15 | AS11: =IFERROR(((AO11*AM11)+(AP11*AR11))/SUM(AO11,AR11),"") -> 93.913333 | AT11: =IFERROR(AS11-VLOOKUP(AD11,$B$5:$H$14,7,FALSE),"") -> -13.259109 | AU11: =AL11-AT11 -> 16.794396 | AW11: 87 | AX11: Walker/Cory | AY11: Eric/Blake | AZ11: 111.77333 | BA11: -5.813252 | BB11: 12 | BC11: 89.17 | BD11: -3.5535294 | BE11: 8 | BF11: 102.732 | BG11: -3.5833333 | BH11: 97.765 | BI11: -24.62943 | BJ11: 8 | BK11: 96.205 | BL11: -0.83838028 | BM11: 12 | BN11: 96.829 | BO11: -13.565933 | BP11: 9.9826
B12: Pat/Tucker | C12: =COUNTIF('Regular Season'!R:R,'Summary Page'!B12) -> 84 | D12: =COUNTIF('Regular Season'!S:S,'Summary Page'!B12) -> 88 | E12: =IFERROR(C12/SUM(C12:D12),"") -> 0.48837209 | F12: =SUMIF('Regular Season'!R:R,'Summary Page'!B12,'Regular Season'!T:T)+SUMIF('Regular Season'!S:S,'Summary Page'!B12,'Regular Season'!U:U) -> 18433.66 | G12: =SUMIF('Regular Season'!R:R,'Summary Page'!B12,'Regular Season'!U:U)+SUMIF('Regular Season'!S:S,'Summary Page'!B12,'Regular Season'!T:T) -> 18937.73 | H12: =F12/SUM(C12:D12) -> 107.17244 | I12: =AVERAGEIF(Tables!C:C,'Summary Page'!B12,Tables!D:D) -> 5.8461538 | J12: =AVERAGEIF('Regular Season'!R:R,'Summary Page'!B12,'Regular Season'!T:T) -> 120.44238 | K12: =AVERAGEIF('Regular Season'!S:S,'Summary Page'!B12,'Regular Season'!U:U) -> 94.505682 | M12: 8 | N12: =VLOOKUP(M12,'Regular Season'!F:U,13,FALSE) -> Trent/Colin | O12: =VLOOKUP(M12,'Regular Season'!F:U,14,FALSE) -> Pat/Tucker | P12: =VLOOKUP(M12,'Regular Season'!F:U,3,FALSE) -> 2022 | Q12: =VLOOKUP(M12,'Regular Season'!F:U,4,FALSE) -> 10 | R12: =VLOOKUP(M12,'Regular Season'!F:U,15,FALSE) -> 173.08 | T12: 8 | U12: =VLOOKUP(T12,Tables!A:K,3,FALSE) -> Pat/Tucker | V12: =VLOOKUP(T12,Tables!A:K,2,FALSE) -> 2020 | W12: =VLOOKUP(T12,Tables!A:K,5,FALSE) -> 3 | X12: =VLOOKUP(T12,Tables!A:K,6,FALSE) -> 10 | Y12: =VLOOKUP(T12,Tables!A:K,7,FALSE) -> 3 | Z12: =VLOOKUP(T12,Tables!A:K,11,FALSE) -> 122.18462 | AB12: 8 | AC12: Brian/Travis | AD12: Trent/Colin | AE12: =AVERAGEIFS('Regular Season'!T:T,'Regular Season'!R:R,'Summary Page'!AC12,'Regular Season'!S:S,'Summary Page'!AD12) -> 117.52889 | AF12: =AE12-VLOOKUP(AC12,'Summary Page (2)'!$B$5:$K$14,9,FALSE) -> -0.40808786 | AG12: =COUNTIFS('Regular Season'!R:R,'Summary Page'!AC12,'Regular Season'!S:S,'Summary Page'!AD12) -> 9 | AH12: =AVERAGEIFS('Regular Season'!U:U,'Regular Season'!S:S,'Summary Page'!AC12,'Regular Season'!R:R,'Summary Page'!AD12) -> 98.6425 | AI12: =AH12-VLOOKUP(AC12,'Summary Page (2)'!$B$5:$K$14,10,FALSE) -> 4.5493182 | AJ12: =COUNTIFS('Regular Season'!R:R,'Summary Page'!AD12,'Regular Season'!S:S,'Summary Page'!AC12) -> 16 | AK12: =IFERROR(((AG12*AE12)+(AH12*AJ12))/SUM(AG12,AJ12),"") -> 105.4416 | AL12: =IFERROR(AK12-VLOOKUP(AC12,$B$5:$H$14,7,FALSE),"") -> -0.43644598 | AM12: =AVERAGEIFS('Regular Season'!T:T,'Regular Season'!R:R,'Summary Page'!AD12,'Regular Season'!S:S,'Summary Page'!AC12) -> 119.33125 | AN12: =AM12-VLOOKUP(AD12,'Summary Page (2)'!$B$5:$K$14,9,FALSE) -> -1.4250245 | AO12: =COUNTIFS('Regular Season'!R:R,'Summary Page'!AD12,'Regular Season'!S:S,'Summary Page'!AC12) -> 16 | AP12: =AVERAGEIFS('Regular Season'!U:U,'Regular Season'!S:S,'Summary Page'!AD12,'Regular Season'!R:R,'Summary Page'!AC12) -> 92.011111 | AQ12: =AP12-VLOOKUP(AD12,'Summary Page (2)'!$B$5:$K$14,10,FALSE) -> -4.6813213 | AR12: =COUNTIFS('Regular Season'!R:R,'Summary Page'!AC12,'Regular Season'!S:S,'Summary Page'!AD12) -> 9 | AS12: =IFERROR(((AO12*AM12)+(AP12*AR12))/SUM(AO12,AR12),"") -> 109.496 | AT12: =IFERROR(AS12-VLOOKUP(AD12,$B$5:$H$14,7,FALSE),"") -> -1.1425227 | AU12: =AL12-AT12 -> 0.70607675 | AW12: 37 | AX12: Drew/Cam | AY12: Brian/Travis | AZ12: 116.335 | BA12: 0.79034247 | BB12: 12 | BC12: 100.69429 | BD12: 9.1654545 | BE12: 7 | BF12: 110.57263 | BG12: 7.3560982 | BH12: 124.66571 | BI12: 7.5642857 | BJ12: 7 | BK12: 89.416667 | BL12: -4.1483333 | BM12: 12 | BN12: 102.40316 | BO12: -2.1455088 | BP12: 9.501607
B13: Trent/Colin | C13: =COUNTIF('Regular Season'!R:R,'Summary Page'!B13) -> 102 | D13: =COUNTIF('Regular Season'!S:S,'Summary Page'!B13) -> 74 | E13: =IFERROR(C13/SUM(C13:D13),"") -> 0.57954545 | F13: =SUMIF('Regular Season'!R:R,'Summary Page'!B13,'Regular Season'!T:T)+SUMIF('Regular Season'!S:S,'Summary Page'!B13,'Regular Season'!U:U) -> 19472.38 | G13: =SUMIF('Regular Season'!R:R,'Summary Page'!B13,'Regular Season'!U:U)+SUMIF('Regular Season'!S:S,'Summary Page'!B13,'Regular Season'!T:T) -> 18604.72 | H13: =F13/SUM(C13:D13) -> 110.63852 | I13: =AVERAGEIF(Tables!C:C,'Summary Page'!B13,Tables!D:D) -> 3.9230769 | J13: =AVERAGEIF('Regular Season'!R:R,'Summary Page'!B13,'Regular Season'!T:T) -> 120.75627 | K13: =AVERAGEIF('Regular Season'!S:S,'Summary Page'!B13,'Regular Season'!U:U) -> 96.692432 | M13: 9 | N13: =VLOOKUP(M13,'Regular Season'!F:U,13,FALSE) -> Pat/Tucker | O13: =VLOOKUP(M13,'Regular Season'!F:U,14,FALSE) -> Eric/Blake | P13: =VLOOKUP(M13,'Regular Season'!F:U,3,FALSE) -> 2014 | Q13: =VLOOKUP(M13,'Regular Season'!F:U,4,FALSE) -> 6 | R13: =VLOOKUP(M13,'Regular Season'!F:U,15,FALSE) -> 172.5 | T13: 9 | U13: =VLOOKUP(T13,Tables!A:K,3,FALSE) -> Trent/Colin | V13: =VLOOKUP(T13,Tables!A:K,2,FALSE) -> 2023 | W13: =VLOOKUP(T13,Tables!A:K,5,FALSE) -> 1 | X13: =VLOOKUP(T13,Tables!A:K,6,FALSE) -> 9 | Y13: =VLOOKUP(T13,Tables!A:K,7,FALSE) -> 5 | Z13: =VLOOKUP(T13,Tables!A:K,11,FALSE) -> 121.60286 | AB13: 9 | AC13: Brian/Travis | AD13: Walker/Cory | AE13: =AVERAGEIFS('Regular Season'!T:T,'Regular Season'!R:R,'Summary Page'!AC13,'Regular Season'!S:S,'Summary Page'!AD13) -> 123.56889 | AF13: =AE13-VLOOKUP(AC13,'Summary Page (2)'!$B$5:$K$14,9,FALSE) -> 5.6319121 | AG13: =COUNTIFS('Regular Season'!R:R,'Summary Page'!AC13,'Regular Season'!S:S,'Summary Page'!AD13) -> 9 | AH13: =AVERAGEIFS('Regular Season'!U:U,'Regular Season'!S:S,'Summary Page'!AC13,'Regular Season'!R:R,'Summary Page'!AD13) -> 69.088 | AI13: =AH13-VLOOKUP(AC13,'Summary Page (2)'!$B$5:$K$14,10,FALSE) -> -25.005182 | AJ13: =COUNTIFS('Regular Season'!R:R,'Summary Page'!AD13,'Regular Season'!S:S,'Summary Page'!AC13) -> 5 | AK13: =IFERROR(((AG13*AE13)+(AH13*AJ13))/SUM(AG13,AJ13),"") -> 104.11143 | AL13: =IFERROR(AK13-VLOOKUP(AC13,$B$5:$H$14,7,FALSE),"") -> -1.7666174 | AM13: =AVERAGEIFS('Regular Season'!T:T,'Regular Season'!R:R,'Summary Page'!AD13,'Regular Season'!S:S,'Summary Page'!AC13) -> 106.884 | AN13: =AM13-VLOOKUP(AD13,'Summary Page (2)'!$B$5:$K$14,9,FALSE) -> -9.1938261 | AO13: =COUNTIFS('Regular Season'!R:R,'Summary Page'!AD13,'Regular Season'!S:S,'Summary Page'!AC13) -> 5 | AP13: =AVERAGEIFS('Regular Season'!U:U,'Regular Season'!S:S,'Summary Page'!AD13,'Regular Season'!R:R,'Summary Page'!AC13) -> 83.426667 | AQ13: =AP13-VLOOKUP(AD13,'Summary Page (2)'!$B$5:$K$14,10,FALSE) -> -11.343577 | AR13: =COUNTIFS('Regular Season'!R:R,'Summary Page'!AC13,'Regular Season'!S:S,'Summary Page'!AD13) -> 9 | AS13: =IFERROR(((AO13*AM13)+(AP13*AR13))/SUM(AO13,AR13),"") -> 91.804286 | AT13: =IFERROR(AS13-VLOOKUP(AD13,$B$5:$H$14,7,FALSE),"") -> -14.232036 | AU13: =AL13-AT13 -> 12.465419 | AW13: 16 | AX13: Clay/Ryan | AY13: Pat/Tucker | AZ13: 123.16333 | BA13: 4.1848523 | BB13: 6 | BC13: 95.24 | BD13: 2.4180282 | BE13: 5 | BF13: 110.47091 | BG13: 3.8731758 | BH13: 113.428 | BI13: -7.1452432 | BJ13: 5 | BK13: 92.123333 | BL13: -1.2745614 | BM13: 6 | BN13: 101.80727 | BO13: -4.9971273 | BP13: 8.870303
B14: Walker/Cory | C14: =COUNTIF('Regular Season'!R:R,'Summary Page'!B14) -> 92 | D14: =COUNTIF('Regular Season'!S:S,'Summary Page'!B14) -> 82 | E14: =IFERROR(C14/SUM(C14:D14),"") -> 0.52873563 | F14: =SUMIF('Regular Season'!R:R,'Summary Page'!B14,'Regular Season'!T:T)+SUMIF('Regular Season'!S:S,'Summary Page'!B14,'Regular Season'!U:U) -> 18450.32 | G14: =SUMIF('Regular Season'!R:R,'Summary Page'!B14,'Regular Season'!U:U)+SUMIF('Regular Season'!S:S,'Summary Page'!B14,'Regular Season'!T:T) -> 18344.8 | H14: =F14/SUM(C14:D14) -> 106.03632 | I14: =AVERAGEIF(Tables!C:C,'Summary Page'!B14,Tables!D:D) -> 5.2307692 | J14: =AVERAGEIF('Regular Season'!R:R,'Summary Page'!B14,'Regular Season'!T:T) -> 116.07783 | K14: =AVERAGEIF('Regular Season'!S:S,'Summary Page'!B14,'Regular Season'!U:U) -> 94.770244 | M14: 10 | N14: =VLOOKUP(M14,'Regular Season'!F:U,13,FALSE) -> Pat/Tucker | O14: =VLOOKUP(M14,'Regular Season'!F:U,14,FALSE) -> Drew/Cam | P14: =VLOOKUP(M14,'Regular Season'!F:U,3,FALSE) -> 2020 | Q14: =VLOOKUP(M14,'Regular Season'!F:U,4,FALSE) -> 4 | R14: =VLOOKUP(M14,'Regular Season'!F:U,15,FALSE) -> 171.38 | T14: 10 | U14: =VLOOKUP(T14,Tables!A:K,3,FALSE) -> Walker/Cory | V14: =VLOOKUP(T14,Tables!A:K,2,FALSE) -> 2022 | W14: =VLOOKUP(T14,Tables!A:K,5,FALSE) -> 1 | X14: =VLOOKUP(T14,Tables!A:K,6,FALSE) -> 10 | Y14: =VLOOKUP(T14,Tables!A:K,7,FALSE) -> 4 | Z14: =VLOOKUP(T14,Tables!A:K,11,FALSE) -> 120.78 | AB14: 10 | AC14: Clay/Ryan | AD14: Brian/Travis | AE14: =AVERAGEIFS('Regular Season'!T:T,'Regular Season'!R:R,'Summary Page'!AC14,'Regular Season'!S:S,'Summary Page'!AD14) -> 122.76222 | AF14: =AE14-VLOOKUP(AC14,'Summary Page (2)'!$B$5:$K$14,9,FALSE) -> 3.2886738 | AG14: =COUNTIFS('Regular Season'!R:R,'Summary Page'!AC14,'Regular Season'!S:S,'Summary Page'!AD14) -> 9 | AH14: =AVERAGEIFS('Regular Season'!U:U,'Regular Season'!S:S,'Summary Page'!AC14,'Regular Season'!R:R,'Summary Page'!AD14) -> 82.661818 | AI14: =AH14-VLOOKUP(AC14,'Summary Page (2)'!$B$5:$K$14,10,FALSE) -> -10.411515 | AJ14: =COUNTIFS('Regular Season'!R:R,'Summary Page'!AD14,'Regular Season'!S:S,'Summary Page'!AC14) -> 11 | AK14: =IFERROR(((AG14*AE14)+(AH14*AJ14))/SUM(AG14,AJ14),"") -> 100.707 | AL14: =IFERROR(AK14-VLOOKUP(AC14,$B$5:$H$14,7,FALSE),"") -> -6.4767931 | AM14: =AVERAGEIFS('Regular Season'!T:T,'Regular Season'!R:R,'Summary Page'!AD14,'Regular Season'!S:S,'Summary Page'!AC14) -> 104.04545 | AN14: =AM14-VLOOKUP(AD14,'Summary Page (2)'!$B$5:$K$14,9,FALSE) -> -13.891522 | AO14: =COUNTIFS('Regular Season'!R:R,'Summary Page'!AD14,'Regular Season'!S:S,'Summary Page'!AC14) -> 11 | AP14: =AVERAGEIFS('Regular Season'!U:U,'Regular Season'!S:S,'Summary Page'!AD14,'Regular Season'!R:R,'Summary Page'!AC14) -> 91.068889 | AQ14: =AP14-VLOOKUP(AD14,'Summary Page (2)'!$B$5:$K$14,10,FALSE) -> -3.0242929 | AR14: =COUNTIFS('Regular Season'!R:R,'Summary Page'!AC14,'Regular Season'!S:S,'Summary Page'!AD14) -> 9 | AS14: =IFERROR(((AO14*AM14)+(AP14*AR14))/SUM(AO14,AR14),"") -> 98.206 | AT14: =IFERROR(AS14-VLOOKUP(AD14,$B$5:$H$14,7,FALSE),"") -> -7.672046 | AU14: =AL14-AT14 -> 1.1952529 | AW14: 5 | AX14: Brian/Travis | AY14: Eric/Blake | AZ14: 125.95714 | BA14: 8.8557143 | BB14: 7 | BC14: 94.846667 | BD14: 1.2816667 | BE14: 6 | BF14: 111.59846 | BG14: 7.0497949 | BH14: 114.76333 | BI14: -7.631097 | BJ14: 6 | BK14: 104.25714 | BL14: 7.2137626 | BM14: 7 | BN14: 109.10615 | BO14: -1.2887795 | BP14: 8.3385744
AB15: 11 | AC15: Clay/Ryan | AD15: Dave/Nolan | AE15: =AVERAGEIFS('Regular Season'!T:T,'Regular Season'!R:R,'Summary Page'!AC15,'Regular Season'!S:S,'Summary Page'!AD15) -> 122.782 | AF15: =AE15-VLOOKUP(AC15,'Summary Page (2)'!$B$5:$K$14,9,FALSE) -> 3.3084516 | AG15: =COUNTIFS('Regular Season'!R:R,'Summary Page'!AC15,'Regular Season'!S:S,'Summary Page'!AD15) -> 10 | AH15: =AVERAGEIFS('Regular Season'!U:U,'Regular Season'!S:S,'Summary Page'!AC15,'Regular Season'!R:R,'Summary Page'!AD15) -> 94.696 | AI15: =AH15-VLOOKUP(AC15,'Summary Page (2)'!$B$5:$K$14,10,FALSE) -> 1.6226667 | AJ15: =COUNTIFS('Regular Season'!R:R,'Summary Page'!AD15,'Regular Season'!S:S,'Summary Page'!AC15) -> 10 | AK15: =IFERROR(((AG15*AE15)+(AH15*AJ15))/SUM(AG15,AJ15),"") -> 108.739 | AL15: =IFERROR(AK15-VLOOKUP(AC15,$B$5:$H$14,7,FALSE),"") -> 1.5552069 | AM15: =AVERAGEIFS('Regular Season'!T:T,'Regular Season'!R:R,'Summary Page'!AD15,'Regular Season'!S:S,'Summary Page'!AC15) -> 118.03 | AN15: =AM15-VLOOKUP(AD15,'Summary Page (2)'!$B$5:$K$14,9,FALSE) -> -3.6697531 | AO15: =COUNTIFS('Regular Season'!R:R,'Summary Page'!AD15,'Regular Season'!S:S,'Summary Page'!AC15) -> 10 | AP15: =AVERAGEIFS('Regular Season'!U:U,'Regular Season'!S:S,'Summary Page'!AD15,'Regular Season'!R:R,'Summary Page'!AC15) -> 93.942 | AQ15: =AP15-VLOOKUP(AD15,'Summary Page (2)'!$B$5:$K$14,10,FALSE) -> -0.93408696 | AR15: =COUNTIFS('Regular Season'!R:R,'Summary Page'!AC15,'Regular Season'!S:S,'Summary Page'!AD15) -> 10 | AS15: =IFERROR(((AO15*AM15)+(AP15*AR15))/SUM(AO15,AR15),"") -> 105.986 | AT15: =IFERROR(AS15-VLOOKUP(AD15,$B$5:$H$14,7,FALSE),"") -> -1.4491445 | AU15: =AL15-AT15 -> 3.0043514 | AW15: 23 | AX15: Dave/Nolan | AY15: Eric/Blake | AZ15: 127.95 | BA15: 5.4673684 | BB15: 10 | BC15: 102.48222 | BD15: 6.1643844 | BE15: 9 | BF15: 115.88632 | BG15: 6.3116491 | BH15: 126.1 | BI15: 3.7055696 | BJ15: 9 | BK15: 92.956 | BL15: -4.0873803 | BM15: 10 | BN15: 108.65579 | BO15: -1.7391439 | BP15: 8.050793
B16: Historical Playoff Table | M16: Biggest Regular Season Beatdowns | T16: Highest Points Total in a Matchup | AB16: 12 | AC16: Clay/Ryan | AD16: David/Marshall | AE16: =AVERAGEIFS('Regular Season'!T:T,'Regular Season'!R:R,'Summary Page'!AC16,'Regular Season'!S:S,'Summary Page'!AD16) -> 116.824 | AF16: =AE16-VLOOKUP(AC16,'Summary Page (2)'!$B$5:$K$14,9,FALSE) -> -2.6495484 | AG16: =COUNTIFS('Regular Season'!R:R,'Summary Page'!AC16,'Regular Season'!S:S,'Summary Page'!AD16) -> 15 | AH16: =AVERAGEIFS('Regular Season'!U:U,'Regular Season'!S:S,'Summary Page'!AC16,'Regular Season'!R:R,'Summary Page'!AD16) -> 96.59 | AI16: =AH16-VLOOKUP(AC16,'Summary Page (2)'!$B$5:$K$14,10,FALSE) -> 3.5166667 | AJ16: =COUNTIFS('Regular Season'!R:R,'Summary Page'!AD16,'Regular Season'!S:S,'Summary Page'!AC16) -> 8 | AK16: =IFERROR(((AG16*AE16)+(AH16*AJ16))/SUM(AG16,AJ16),"") -> 109.78609 | AL16: =IFERROR(AK16-VLOOKUP(AC16,$B$5:$H$14,7,FALSE),"") -> 2.6022939 | AM16: =AVERAGEIFS('Regular Season'!T:T,'Regular Season'!R:R,'Summary Page'!AD16,'Regular Season'!S:S,'Summary Page'!AC16) -> 129.025 | AN16: =AM16-VLOOKUP(AD16,'Summary Page (2)'!$B$5:$K$14,9,FALSE) -> 9.8368841 | AO16: =COUNTIFS('Regular Season'!R:R,'Summary Page'!AD16,'Regular Season'!S:S,'Summary Page'!AC16) -> 8 | AP16: =AVERAGEIFS('Regular Season'!U:U,'Regular Season'!S:S,'Summary Page'!AD16,'Regular Season'!R:R,'Summary Page'!AC16) -> 93.478667 | AQ16: =AP16-VLOOKUP(AD16,'Summary Page (2)'!$B$5:$K$14,10,FALSE) -> 2.9322516 | AR16: =COUNTIFS('Regular Season'!R:R,'Summary Page'!AC16,'Regular Season'!S:S,'Summary Page'!AD16) -> 15 | AS16: =IFERROR(((AO16*AM16)+(AP16*AR16))/SUM(AO16,AR16),"") -> 105.84261 | AT16: =IFERROR(AS16-VLOOKUP(AD16,$B$5:$H$14,7,FALSE),"") -> 4.0031801 | AU16: =AL16-AT16 -> -1.4008863 | AW16: 61 | AX16: Graham/Michael | AY16: Pat/Tucker | AZ16: 131.852 | BA16: 9.4250556 | BB16: 10 | BC16: 102.70222 | BD16: 4.3052991 | BE16: 9 | BF16: 118.04421 | BG16: 8.1128772 | BH16: 120.14667 | BI16: -0.42657658 | BJ16: 9 | BK16: 95.564 | BL16: 2.1661053 | BM16: 10 | BN16: 107.20842 | BO16: 0.40402105 | BP16: 7.7088561
B17: Team | C17: Wins | D17: Losses | E17: Pct | F17: Pts For | G17: Apps | H17: Ringz | I17: Semis | M17: Rank | N17: Owner | O17: Opponent | P17: Season | Q17: Week | R17: Margin | T17: Rank | U17: Winner | V17: Loser | W17: Season | X17: Week | Y17: Total Pts | AB17: 13 | AC17: Clay/Ryan | AD17: Drew/Cam | AE17: =AVERAGEIFS('Regular Season'!T:T,'Regular Season'!R:R,'Summary Page'!AC17,'Regular Season'!S:S,'Summary Page'!AD17) -> 120.00667 | AF17: =AE17-VLOOKUP(AC17,'Summary Page (2)'!$B$5:$K$14,9,FALSE) -> 0.53311828 | AG17: =COUNTIFS('Regular Season'!R:R,'Summary Page'!AC17,'Regular Season'!S:S,'Summary Page'!AD17) -> 12 | AH17: =AVERAGEIFS('Regular Season'!U:U,'Regular Season'!S:S,'Summary Page'!AC17,'Regular Season'!R:R,'Summary Page'!AD17) -> 98.265714 | AI17: =AH17-VLOOKUP(AC17,'Summary Page (2)'!$B$5:$K$14,10,FALSE) -> 5.192381 | AJ17: =COUNTIFS('Regular Season'!R:R,'Summary Page'!AD17,'Regular Season'!S:S,'Summary Page'!AC17) -> 7 | AK17: =IFERROR(((AG17*AE17)+(AH17*AJ17))/SUM(AG17,AJ17),"") -> 111.99684 | AL17: =IFERROR(AK17-VLOOKUP(AC17,$B$5:$H$14,7,FALSE),"") -> 4.813049 | AM17: =AVERAGEIFS('Regular Season'!T:T,'Regular Season'!R:R,'Summary Page'!AD17,'Regular Season'!S:S,'Summary Page'!AC17) -> 120.77714 | AN17: =AM17-VLOOKUP(AD17,'Summary Page (2)'!$B$5:$K$14,9,FALSE) -> 4.936899 | AO17: =COUNTIFS('Regular Season'!R:R,'Summary Page'!AD17,'Regular Season'!S:S,'Summary Page'!AC17) -> 7 | AP17: =AVERAGEIFS('Regular Season'!U:U,'Regular Season'!S:S,'Summary Page'!AD17,'Regular Season'!R:R,'Summary Page'!AC17) -> 95.321667 | AQ17: =AP17-VLOOKUP(AD17,'Summary Page (2)'!$B$5:$K$14,10,FALSE) -> 2.4709058 | AR17: =COUNTIFS('Regular Season'!R:R,'Summary Page'!AC17,'Regular Season'!S:S,'Summary Page'!AD17) -> 12 | AS17: =IFERROR(((AO17*AM17)+(AP17*AR17))/SUM(AO17,AR17),"") -> 104.7 | AT17: =IFERROR(AS17-VLOOKUP(AD17,$B$5:$H$14,7,FALSE),"") -> 1.0151149 | AU17: =AL17-AT17 -> 3.7979341 | AW17: 52 | AX17: Eric/Blake | AY17: Pat/Tucker | AZ17: 134.75333 | BA17: 12.358903 | BB17: 9 | BC17: 107.4525 | BD17: 10.40912 | BE17: 8 | BF17: 121.90588 | BG17: 11.510949 | BH17: 123.05 | BI17: 2.4767568 | BJ17: 8 | BK17: 101.32222 | BL17: 7.9243275 | BM17: 9 | BN17: 111.54706 | BO17: 4.7426588 | BP17: 6.7682902
B18: Brian/Travis | C18: =COUNTIF(Playoffs!O:O,'Summary Page'!B18) -> 2 | D18: =COUNTIF(Playoffs!P:P,'Summary Page'!B18) -> 11 | E18: =IFERROR(C18/SUM(C18:D18),"") -> 0.15384615 | F18: =SUMIF(Playoffs!O:O,'Summary Page'!B18,Playoffs!Q:Q)+SUMIF(Playoffs!P:P,'Summary Page'!B18,Playoffs!R:R) -> 1354.66 | G18: =COUNTIFS(Tables!C:C,'Summary Page'!B18,Tables!H:H,"Y") -> 8 | H18: =COUNTIFS(Tables!E:E,"1",Tables!C:C,'Summary Page'!B18) -> 0 | I18: =COUNTIFS(Tables!E:E,"1",Tables!C:C,'Summary Page'!B18)+COUNTIFS(Tables!E:E,"2",Tables!C:C,'Summary Page'!B18)+COUNTIFS(Tables!E:E,"3",Tables!C:C,'Summary Page'!B18)+COUNTIFS(Tables!E:E,"4",Tables!C:C,'Summary Page'!B18) -> 3 | M18: 1 | N18: =VLOOKUP(M5,'Regular Season'!D:U,15,FALSE) -> Dave/Nolan | O18: =VLOOKUP(M5,'Regular Season'!D:U,16,FALSE) -> Walker/Cory | P18: =VLOOKUP(M5,'Regular Season'!D:U,5,FALSE) -> 2023 | Q18: =VLOOKUP(M5,'Regular Season'!D:U,6,FALSE) -> 13 | R18: =VLOOKUP(M5,'Regular Season'!D:U,14,FALSE) -> 99.4 | T18: 1 | U18: =VLOOKUP(T18,'Regular Season'!E:U,14,FALSE) -> Graham/Michael | V18: =VLOOKUP(T18,'Regular Season'!E:U,15,FALSE) -> Eric/Blake | W18: =VLOOKUP(T18,'Regular Season'!E:U,4,FALSE) -> 2023 | X18: =VLOOKUP(T18,'Regular Season'!E:U,5,FALSE) -> 3 | Y18: =VLOOKUP(T18,'Regular Season'!E:U,12,FALSE) -> 337.84 | AB18: 14 | AC18: Clay/Ryan | AD18: Eric/Blake | AE18: =AVERAGEIFS('Regular Season'!T:T,'Regular Season'!R:R,'Summary Page'!AC18,'Regular Season'!S:S,'Summary Page'!AD18) -> 109.712 | AF18: =AE18-VLOOKUP(AC18,'Summary Page (2)'!$B$5:$K$14,9,FALSE) -> -9.7615484 | AG18: =COUNTIFS('Regular Season'!R:R,'Summary Page'!AC18,'Regular Season'!S:S,'Summary Page'!AD18) -> 10 | AH18: =AVERAGEIFS('Regular Season'!U:U,'Regular Season'!S:S,'Summary Page'!AC18,'Regular Season'!R:R,'Summary Page'!AD18) -> 88.766667 | AI18: =AH18-VLOOKUP(AC18,'Summary Page (2)'!$B$5:$K$14,10,FALSE) -> -4.3066667 | AJ18: =COUNTIFS('Regular Season'!R:R,'Summary Page'!AD18,'Regular Season'!S:S,'Summary Page'!AC18) -> 9 | AK18: =IFERROR(((AG18*AE18)+(AH18*AJ18))/SUM(AG18,AJ18),"") -> 99.790526 | AL18: =IFERROR(AK18-VLOOKUP(AC18,$B$5:$H$14,7,FALSE),"") -> -7.3932668 | AM18: =AVERAGEIFS('Regular Season'!T:T,'Regular Season'!R:R,'Summary Page'!AD18,'Regular Season'!S:S,'Summary Page'!AC18) -> 114.54222 | AN18: =AM18-VLOOKUP(AD18,'Summary Page (2)'!$B$5:$K$14,9,FALSE) -> -7.8004151 | AO18: =COUNTIFS('Regular Season'!R:R,'Summary Page'!AD18,'Regular Season'!S:S,'Summary Page'!AC18) -> 9 | AP18: =AVERAGEIFS('Regular Season'!U:U,'Regular Season'!S:S,'Summary Page'!AD18,'Regular Season'!R:R,'Summary Page'!AC18) -> 86.934 | AQ18: =AP18-VLOOKUP(AD18,'Summary Page (2)'!$B$5:$K$14,10,FALSE) -> -9.466 | AR18: =COUNTIFS('Regular Season'!R:R,'Summary Page'!AC18,'Regular Season'!S:S,'Summary Page'!AD18) -> 10 | AS18: =IFERROR(((AO18*AM18)+(AP18*AR18))/SUM(AO18,AR18),"") -> 100.01158 | AT18: =IFERROR(AS18-VLOOKUP(AD18,$B$5:$H$14,7,FALSE),"") -> -9.9561222 | AU18: =AL18-AT18 -> 2.5628554 | AW18: 71 | AX18: Pat/Tucker | AY18: Trent/Colin | AZ18: 123.306 | BA18: 2.7327568 | BB18: 10 | BC18: 92.61 | BD18: -0.78789474 | BE18: 8 | BF18: 109.66333 | BG18: 2.8589333 | BH18: 122.3625 | BI18: 1.2762079 | BJ18: 8 | BK18: 94.23 | BL18: -0.55590164 | BM18: 10 | BN18: 106.73333 | BO18: -3.6574667 | BP18: 6.5164
B19: Clay/Ryan | C19: =COUNTIF(Playoffs!O:O,'Summary Page'!B19) -> 13 | D19: =COUNTIF(Playoffs!P:P,'Summary Page'!B19) -> 7 | E19: =IFERROR(C19/SUM(C19:D19),"") -> 0.65 | F19: =SUMIF(Playoffs!O:O,'Summary Page'!B19,Playoffs!Q:Q)+SUMIF(Playoffs!P:P,'Summary Page'!B19,Playoffs!R:R) -> 2398.04 | G19: =COUNTIFS(Tables!C:C,'Summary Page'!B19,Tables!H:H,"Y") -> 10 | H19: =COUNTIFS(Tables!E:E,"1",Tables!C:C,'Summary Page'!B19) -> 3 | I19: =COUNTIFS(Tables!E:E,"1",Tables!C:C,'Summary Page'!B19)+COUNTIFS(Tables!E:E,"2",Tables!C:C,'Summary Page'!B19)+COUNTIFS(Tables!E:E,"3",Tables!C:C,'Summary Page'!B19)+COUNTIFS(Tables!E:E,"4",Tables!C:C,'Summary Page'!B19) -> 6 | M19: 2 | N19: =VLOOKUP(M6,'Regular Season'!D:U,15,FALSE) -> Pat/Tucker | O19: =VLOOKUP(M6,'Regular Season'!D:U,16,FALSE) -> David/Marshall | P19: =VLOOKUP(M6,'Regular Season'!D:U,5,FALSE) -> 2022 | Q19: =VLOOKUP(M6,'Regular Season'!D:U,6,FALSE) -> 8 | R19: =VLOOKUP(M6,'Regular Season'!D:U,14,FALSE) -> 96.62 | T19: 2 | U19: =VLOOKUP(T19,'Regular Season'!E:U,14,FALSE) -> Clay/Ryan | V19: =VLOOKUP(T19,'Regular Season'!E:U,15,FALSE) -> Dave/Nolan | W19: =VLOOKUP(T19,'Regular Season'!E:U,4,FALSE) -> 2019 | X19: =VLOOKUP(T19,'Regular Season'!E:U,5,FALSE) -> 5 | Y19: =VLOOKUP(T19,'Regular Season'!E:U,12,FALSE) -> 328.98 | AB19: 15 | AC19: Clay/Ryan | AD19: Graham/Michael | AE19: =AVERAGEIFS('Regular Season'!T:T,'Regular Season'!R:R,'Summary Page'!AC19,'Regular Season'!S:S,'Summary Page'!AD19) -> 128.18 | AF19: =AE19-VLOOKUP(AC19,'Summary Page (2)'!$B$5:$K$14,9,FALSE) -> 8.7064516 | AG19: =COUNTIFS('Regular Season'!R:R,'Summary Page'!AC19,'Regular Season'!S:S,'Summary Page'!AD19) -> 6 | AH19: =AVERAGEIFS('Regular Season'!U:U,'Regular Season'!S:S,'Summary Page'!AC19,'Regular Season'!R:R,'Summary Page'!AD19) -> 93.75 | AI19: =AH19-VLOOKUP(AC19,'Summary Page (2)'!$B$5:$K$14,10,FALSE) -> 0.67666667 | AJ19: =COUNTIFS('Regular Season'!R:R,'Summary Page'!AD19,'Regular Season'!S:S,'Summary Page'!AC19) -> 10 | AK19: =IFERROR(((AG19*AE19)+(AH19*AJ19))/SUM(AG19,AJ19),"") -> 106.66125 | AL19: =IFERROR(AK19-VLOOKUP(AC19,$B$5:$H$14,7,FALSE),"") -> -0.5225431 | AM19: =AVERAGEIFS('Regular Season'!T:T,'Regular Season'!R:R,'Summary Page'!AD19,'Regular Season'!S:S,'Summary Page'!AC19) -> 124.2 | AN19: =AM19-VLOOKUP(AD19,'Summary Page (2)'!$B$5:$K$14,9,FALSE) -> -0.95866667 | AO19: =COUNTIFS('Regular Season'!R:R,'Summary Page'!AD19,'Regular Season'!S:S,'Summary Page'!AC19) -> 10 | AP19: =AVERAGEIFS('Regular Season'!U:U,'Regular Season'!S:S,'Summary Page'!AD19,'Regular Season'!R:R,'Summary Page'!AC19) -> 98.09 | AQ19: =AP19-VLOOKUP(AD19,'Summary Page (2)'!$B$5:$K$14,10,FALSE) -> -0.85714286 | AR19: =COUNTIFS('Regular Season'!R:R,'Summary Page'!AC19,'Regular Season'!S:S,'Summary Page'!AD19) -> 6 | AS19: =IFERROR(((AO19*AM19)+(AP19*AR19))/SUM(AO19,AR19),"") -> 114.40875 | AT19: =IFERROR(AS19-VLOOKUP(AD19,$B$5:$H$14,7,FALSE),"") -> 1.9039224 | AU19: =AL19-AT19 -> -2.4264655 | AW19: 66 | AX19: Pat/Tucker | AY19: Dave/Nolan | AZ19: 134.33143 | BA19: 13.758185 | BB19: 7 | BC19: 86.457778 | BD19: -6.940117 | BE19: 9 | BF19: 107.4025 | BG19: 0.5981 | BH19: 108.73333 | BI19: -13.749298 | BJ19: 9 | BK19: 98.057143 | BL19: 1.739305 | BM19: 7 | BN19: 104.0625 | BO19: -5.5121667 | BP19: 6.1102667
B20: Dave/Nolan | C20: =COUNTIF(Playoffs!O:O,'Summary Page'!B20) -> 6 | D20: =COUNTIF(Playoffs!P:P,'Summary Page'!B20) -> 8 | E20: =IFERROR(C20/SUM(C20:D20),"") -> 0.42857143 | F20: =SUMIF(Playoffs!O:O,'Summary Page'!B20,Playoffs!Q:Q)+SUMIF(Playoffs!P:P,'Summary Page'!B20,Playoffs!R:R) -> 1523.82 | G20: =COUNTIFS(Tables!C:C,'Summary Page'!B20,Tables!H:H,"Y") -> 7 | H20: =COUNTIFS(Tables!E:E,"1",Tables!C:C,'Summary Page'!B20) -> 0 | I20: =COUNTIFS(Tables!E:E,"1",Tables!C:C,'Summary Page'!B20)+COUNTIFS(Tables!E:E,"2",Tables!C:C,'Summary Page'!B20)+COUNTIFS(Tables!E:E,"3",Tables!C:C,'Summary Page'!B20)+COUNTIFS(Tables!E:E,"4",Tables!C:C,'Summary Page'!B20) -> 5 | M20: 3 | N20: =VLOOKUP(M7,'Regular Season'!D:U,15,FALSE) -> Pat/Tucker | O20: =VLOOKUP(M7,'Regular Season'!D:U,16,FALSE) -> Dave/Nolan | P20: =VLOOKUP(M7,'Regular Season'!D:U,5,FALSE) -> 2022 | Q20: =VLOOKUP(M7,'Regular Season'!D:U,6,FALSE) -> 2 | R20: =VLOOKUP(M7,'Regular Season'!D:U,14,FALSE) -> 92.72 | T20: 3 | U20: =VLOOKUP(T20,'Regular Season'!E:U,14,FALSE) -> Eric/Blake | V20: =VLOOKUP(T20,'Regular Season'!E:U,15,FALSE) -> Dave/Nolan | W20: =VLOOKUP(T20,'Regular Season'!E:U,4,FALSE) -> 2021 | X20: =VLOOKUP(T20,'Regular Season'!E:U,5,FALSE) -> 5 | Y20: =VLOOKUP(T20,'Regular Season'!E:U,12,FALSE) -> 315.46 | AB20: 16 | AC20: Clay/Ryan | AD20: Pat/Tucker | AE20: =AVERAGEIFS('Regular Season'!T:T,'Regular Season'!R:R,'Summary Page'!AC20,'Regular Season'!S:S,'Summary Page'!AD20) -> 126.92571 | AF20: =AE20-VLOOKUP(AC20,'Summary Page (2)'!$B$5:$K$14,9,FALSE) -> 7.4521659 | AG20: =COUNTIFS('Regular Season'!R:R,'Summary Page'!AC20,'Regular Season'!S:S,'Summary Page'!AD20) -> 7 | AH20: =AVERAGEIFS('Regular Season'!U:U,'Regular Season'!S:S,'Summary Page'!AC20,'Regular Season'!R:R,'Summary Page'!AD20) -> 95.24 | AI20: =AH20-VLOOKUP(AC20,'Summary Page (2)'!$B$5:$K$14,10,FALSE) -> 2.1666667 | AJ20: =COUNTIFS('Regular Season'!R:R,'Summary Page'!AD20,'Regular Season'!S:S,'Summary Page'!AC20) -> 5 | AK20: =IFERROR(((AG20*AE20)+(AH20*AJ20))/SUM(AG20,AJ20),"") -> 113.72333 | AL20: =IFERROR(AK20-VLOOKUP(AC20,$B$5:$H$14,7,FALSE),"") -> 6.5395402 | AM20: =AVERAGEIFS('Regular Season'!T:T,'Regular Season'!R:R,'Summary Page'!AD20,'Regular Season'!S:S,'Summary Page'!AC20) -> 113.428 | AN20: =AM20-VLOOKUP(AD20,'Summary Page (2)'!$B$5:$K$14,9,FALSE) -> -7.014381 | AO20: =COUNTIFS('Regular Season'!R:R,'Summary Page'!AD20,'Regular Season'!S:S,'Summary Page'!AC20) -> 5 | AP20: =AVERAGEIFS('Regular Season'!U:U,'Regular Season'!S:S,'Summary Page'!AD20,'Regular Season'!R:R,'Summary Page'!AC20) -> 95.065714 | AQ20: =AP20-VLOOKUP(AD20,'Summary Page (2)'!$B$5:$K$14,10,FALSE) -> 0.56003247 | AR20: =COUNTIFS('Regular Season'!R:R,'Summary Page'!AC20,'Regular Season'!S:S,'Summary Page'!AD20) -> 7 | AS20: =IFERROR(((AO20*AM20)+(AP20*AR20))/SUM(AO20,AR20),"") -> 102.71667 | AT20: =IFERROR(AS20-VLOOKUP(AD20,$B$5:$H$14,7,FALSE),"") -> -4.4557752 | AU20: =AL20-AT20 -> 10.995315 | AW20: 86 | AX20: Walker/Cory | AY20: Drew/Cam | AZ20: 112.4925 | BA20: -5.0940854 | BB20: 8 | BC20: 91.316 | BD20: -1.4075294 | BE20: 5 | BF20: 104.34769 | BG20: -1.967641 | BH20: 120.968 | BI20: 5.4233425 | BJ20: 5 | BK20: 80.0025 | BL20: -11.526331 | BM20: 8 | BN20: 95.758462 | BO20: -7.4580718 | BP20: 5.4904308
B21: David/Marshall | C21: =COUNTIF(Playoffs!O:O,'Summary Page'!B21) -> 3 | D21: =COUNTIF(Playoffs!P:P,'Summary Page'!B21) -> 5 | E21: =IFERROR(C21/SUM(C21:D21),"") -> 0.375 | F21: =SUMIF(Playoffs!O:O,'Summary Page'!B21,Playoffs!Q:Q)+SUMIF(Playoffs!P:P,'Summary Page'!B21,Playoffs!R:R) -> 898.54 | G21: =COUNTIFS(Tables!C:C,'Summary Page'!B21,Tables!H:H,"Y") -> 4 | H21: =COUNTIFS(Tables!E:E,"1",Tables!C:C,'Summary Page'!B21) -> 1 | I21: =COUNTIFS(Tables!E:E,"1",Tables!C:C,'Summary Page'!B21)+COUNTIFS(Tables!E:E,"2",Tables!C:C,'Summary Page'!B21)+COUNTIFS(Tables!E:E,"3",Tables!C:C,'Summary Page'!B21)+COUNTIFS(Tables!E:E,"4",Tables!C:C,'Summary Page'!B21) -> 3 | M21: 4 | N21: =VLOOKUP(M8,'Regular Season'!D:U,15,FALSE) -> Graham/Michael | O21: =VLOOKUP(M8,'Regular Season'!D:U,16,FALSE) -> Brian/Travis | P21: =VLOOKUP(M8,'Regular Season'!D:U,5,FALSE) -> 2013 | Q21: =VLOOKUP(M8,'Regular Season'!D:U,6,FALSE) -> 9 | R21: =VLOOKUP(M8,'Regular Season'!D:U,14,FALSE) -> 92 | T21: 4 | U21: =VLOOKUP(T21,'Regular Season'!E:U,14,FALSE) -> Eric/Blake | V21: =VLOOKUP(T21,'Regular Season'!E:U,15,FALSE) -> Pat/Tucker | W21: =VLOOKUP(T21,'Regular Season'!E:U,4,FALSE) -> 2021 | X21: =VLOOKUP(T21,'Regular Season'!E:U,5,FALSE) -> 4 | Y21: =VLOOKUP(T21,'Regular Season'!E:U,12,FALSE) -> 304.12 | AB21: 17 | AC21: Clay/Ryan | AD21: Trent/Colin | AE21: =AVERAGEIFS('Regular Season'!T:T,'Regular Season'!R:R,'Summary Page'!AC21,'Regular Season'!S:S,'Summary Page'!AD21) -> 119.49111 | AF21: =AE21-VLOOKUP(AC21,'Summary Page (2)'!$B$5:$K$14,9,FALSE) -> 0.017562724 | AG21: =COUNTIFS('Regular Season'!R:R,'Summary Page'!AC21,'Regular Season'!S:S,'Summary Page'!AD21) -> 9 | AH21: =AVERAGEIFS('Regular Season'!U:U,'Regular Season'!S:S,'Summary Page'!AC21,'Regular Season'!R:R,'Summary Page'!AD21) -> 95.409091 | AI21: =AH21-VLOOKUP(AC21,'Summary Page (2)'!$B$5:$K$14,10,FALSE) -> 2.3357576 | AJ21: =COUNTIFS('Regular Season'!R:R,'Summary Page'!AD21,'Regular Season'!S:S,'Summary Page'!AC21) -> 11 | AK21: =IFERROR(((AG21*AE21)+(AH21*AJ21))/SUM(AG21,AJ21),"") -> 106.246 | AL21: =IFERROR(AK21-VLOOKUP(AC21,$B$5:$H$14,7,FALSE),"") -> -0.9377931 | AM21: =AVERAGEIFS('Regular Season'!T:T,'Regular Season'!R:R,'Summary Page'!AD21,'Regular Season'!S:S,'Summary Page'!AC21) -> 118.22182 | AN21: =AM21-VLOOKUP(AD21,'Summary Page (2)'!$B$5:$K$14,9,FALSE) -> -2.5344563 | AO21: =COUNTIFS('Regular Season'!R:R,'Summary Page'!AD21,'Regular Season'!S:S,'Summary Page'!AC21) -> 11 | AP21: =AVERAGEIFS('Regular Season'!U:U,'Regular Season'!S:S,'Summary Page'!AD21,'Regular Season'!R:R,'Summary Page'!AC21) -> 99.644444 | AQ21: =AP21-VLOOKUP(AD21,'Summary Page (2)'!$B$5:$K$14,10,FALSE) -> 2.952012 | AR21: =COUNTIFS('Regular Season'!R:R,'Summary Page'!AC21,'Regular Season'!S:S,'Summary Page'!AD21) -> 9 | AS21: =IFERROR(((AO21*AM21)+(AP21*AR21))/SUM(AO21,AR21),"") -> 109.862 | AT21: =IFERROR(AS21-VLOOKUP(AD21,$B$5:$H$14,7,FALSE),"") -> -0.77652273 | AU21: =AL21-AT21 -> -0.16127038 | AW21: 89 | AX21: Walker/Cory | AY21: Pat/Tucker | AZ21: 125.79 | BA21: 8.2034146 | BB21: 8 | BC21: 97.88 | BD21: 5.1564706 | BE21: 8 | BF21: 111.835 | BG21: 5.5196667 | BH21: 118.015 | BI21: -2.5582432 | BJ21: 8 | BK21: 95.8475 | BL21: 2.4496053 | BM21: 8 | BN21: 106.93125 | BO21: 0.12685 | BP21: 5.3928167
B22: Drew/Cam | C22: =COUNTIF(Playoffs!O:O,'Summary Page'!B22) -> 10 | D22: =COUNTIF(Playoffs!P:P,'Summary Page'!B22) -> 8 | E22: =IFERROR(C22/SUM(C22:D22),"") -> 0.55555556 | F22: =SUMIF(Playoffs!O:O,'Summary Page'!B22,Playoffs!Q:Q)+SUMIF(Playoffs!P:P,'Summary Page'!B22,Playoffs!R:R) -> 2256.22 | G22: =COUNTIFS(Tables!C:C,'Summary Page'!B22,Tables!H:H,"Y") -> 8 | H22: =COUNTIFS(Tables!E:E,"1",Tables!C:C,'Summary Page'!B22) -> 1 | I22: =COUNTIFS(Tables!E:E,"1",Tables!C:C,'Summary Page'!B22)+COUNTIFS(Tables!E:E,"2",Tables!C:C,'Summary Page'!B22)+COUNTIFS(Tables!E:E,"3",Tables!C:C,'Summary Page'!B22)+COUNTIFS(Tables!E:E,"4",Tables!C:C,'Summary Page'!B22) -> 6 | M22: 5 | N22: =VLOOKUP(M9,'Regular Season'!D:U,15,FALSE) -> Brian/Travis | O22: =VLOOKUP(M9,'Regular Season'!D:U,16,FALSE) -> Walker/Cory | P22: =VLOOKUP(M9,'Regular Season'!D:U,5,FALSE) -> 2020 | Q22: =VLOOKUP(M9,'Regular Season'!D:U,6,FALSE) -> 12 | R22: =VLOOKUP(M9,'Regular Season'!D:U,14,FALSE) -> 90.98 | T22: 5 | U22: =VLOOKUP(T22,'Regular Season'!E:U,14,FALSE) -> Pat/Tucker | V22: =VLOOKUP(T22,'Regular Season'!E:U,15,FALSE) -> Eric/Blake | W22: =VLOOKUP(T22,'Regular Season'!E:U,4,FALSE) -> 2014 | X22: =VLOOKUP(T22,'Regular Season'!E:U,5,FALSE) -> 6 | Y22: =VLOOKUP(T22,'Regular Season'!E:U,12,FALSE) -> 303.5 | AB22: 18 | AC22: Clay/Ryan | AD22: Walker/Cory | AE22: =AVERAGEIFS('Regular Season'!T:T,'Regular Season'!R:R,'Summary Page'!AC22,'Regular Season'!S:S,'Summary Page'!AD22) -> 117.05467 | AF22: =AE22-VLOOKUP(AC22,'Summary Page (2)'!$B$5:$K$14,9,FALSE) -> -2.4188817 | AG22: =COUNTIFS('Regular Season'!R:R,'Summary Page'!AC22,'Regular Season'!S:S,'Summary Page'!AD22) -> 15 | AH22: =AVERAGEIFS('Regular Season'!U:U,'Regular Season'!S:S,'Summary Page'!AC22,'Regular Season'!R:R,'Summary Page'!AD22) -> 96.002 | AI22: =AH22-VLOOKUP(AC22,'Summary Page (2)'!$B$5:$K$14,10,FALSE) -> 2.9286667 | AJ22: =COUNTIFS('Regular Season'!R:R,'Summary Page'!AD22,'Regular Season'!S:S,'Summary Page'!AC22) -> 10 | AK22: =IFERROR(((AG22*AE22)+(AH22*AJ22))/SUM(AG22,AJ22),"") -> 108.6336 | AL22: =IFERROR(AK22-VLOOKUP(AC22,$B$5:$H$14,7,FALSE),"") -> 1.4498069 | AM22: =AVERAGEIFS('Regular Season'!T:T,'Regular Season'!R:R,'Summary Page'!AD22,'Regular Season'!S:S,'Summary Page'!AC22) -> 121.568 | AN22: =AM22-VLOOKUP(AD22,'Summary Page (2)'!$B$5:$K$14,9,FALSE) -> 5.4901739 | AO22: =COUNTIFS('Regular Season'!R:R,'Summary Page'!AD22,'Regular Season'!S:S,'Summary Page'!AC22) -> 10 | AP22: =AVERAGEIFS('Regular Season'!U:U,'Regular Season'!S:S,'Summary Page'!AD22,'Regular Season'!R:R,'Summary Page'!AC22) -> 93.318667 | AQ22: =AP22-VLOOKUP(AD22,'Summary Page (2)'!$B$5:$K$14,10,FALSE) -> -1.4515772 | AR22: =COUNTIFS('Regular Season'!R:R,'Summary Page'!AC22,'Regular Season'!S:S,'Summary Page'!AD22) -> 15 | AS22: =IFERROR(((AO22*AM22)+(AP22*AR22))/SUM(AO22,AR22),"") -> 104.6184 | AT22: =IFERROR(AS22-VLOOKUP(AD22,$B$5:$H$14,7,FALSE),"") -> -1.4179218 | AU22: =AL22-AT22 -> 2.8677287 | AW22: 41 | AX22: Drew/Cam | AY22: Eric/Blake | AZ22: 123.3 | BA22: 7.7553425 | BB22: 7 | BC22: 95.492 | BD22: 3.9631688 | BE22: 5 | BF22: 111.71333 | BG22: 8.4968 | BH22: 128.712 | BI22: 6.3175696 | BJ22: 5 | BK22: 102.89429 | BL22: 5.8509054 | BM22: 7 | BN22: 113.65167 | BO22: 3.2567333 | BP22: 5.2400667
